<?xml version="1.0" encoding="utf-8"?>
<!-- This URDF was automatically created by SolidWorks to URDF Exporter! Originally created by Stephen Brawner (brawner@gmail.com) 
     Commit Version: 1.5.0-0-g9aa0fdb  Build Version: 1.5.7004.21443
     For more information, please see http://wiki.ros.org/sw_urdf_exporter -->
<robot
  name="srs-77dof">
  <link
    name="base_link">
    <inertial>
      <origin
        xyz="-0.00115430510606862 -0.0008201051198145 0.527097936969844"
        rpy="0 0 0" />
      <mass
        value="41.4264697082622" />
      <inertia
        ixx="0.516190746816454"
        ixy="-1.17375890216909E-07"
        ixz="0.000184806317536522"
        iyy="0.692677706883773"
        iyz="1.75796052634053E-05"
        izz="0.294627182450416" />
    </inertial>
    <visual>
      <origin
        xyz="0 0 0"
        rpy="0 0 0" />
      <geometry>
        <mesh
          filename="package://srs-77dof/meshes/base_link.STL" />
      </geometry>
      <material
        name="">
        <color
          rgba="0.250980392156863 0.250980392156863 0.250980392156863 1" />
      </material>
    </visual>
    <collision>
      <origin
        xyz="0 0 0"
        rpy="0 0 0" />
      <geometry>
        <mesh
          filename="package://srs-77dof/meshes/base_link.STL" />
      </geometry>
    </collision>
  </link>
  <link
    name="link-l1">
    <inertial>
      <origin
        xyz="-0.00534973802702698 4.87983111041035E-05 0.00237312099077956"
        rpy="0 0 0" />
      <mass
        value="2.89937170911004" />
      <inertia
        ixx="0.00501628758764933"
        ixy="-8.65660560888977E-06"
        ixz="0.000499998097645102"
        iyy="0.00488885521969421"
        iyz="3.57871393025778E-06"
        izz="0.00734170120426313" />
    </inertial>
    <visual>
      <origin
        xyz="0 0 0"
        rpy="0 0 0" />
      <geometry>
        <mesh
          filename="package://srs-77dof/meshes/link-l1.STL" />
      </geometry>
      <material
        name="">
        <color
          rgba="0 0.752941176470588 0 1" />
      </material>
    </visual>
    <collision>
      <origin
        xyz="0 0 0"
        rpy="0 0 0" />
      <geometry>
        <mesh
          filename="package://srs-77dof/meshes/link-l1.STL" />
      </geometry>
    </collision>
  </link>
  <joint
    name="joint-l1"
    type="revolute">
    <origin
      xyz="-0.3325 0 0.53254"
      rpy="-1.5708 0 -3.1416" />
    <parent
      link="base_link" />
    <child
      link="link-l1" />
    <axis
      xyz="-1 0 0" />
    <limit
      lower="-6.28"
      upper="6.28"
      effort="150"
      velocity="3.15" />
    <safety_controller
      k_velocity="0" />
  </joint>
  <link
    name="link-l2">
    <inertial>
      <origin
        xyz="-0.0180744791124767 6.76109620012522E-07 0.150905771502013"
        rpy="0 0 0" />
      <mass
        value="4.49590564030825" />
      <inertia
        ixx="0.00898207431263908"
        ixy="2.10768301107502E-06"
        ixz="-0.000963599700576106"
        iyy="0.00840631603447999"
        iyz="1.11909599207401E-06"
        izz="0.00601564825314428" />
    </inertial>
    <visual>
      <origin
        xyz="0 0 0"
        rpy="0 0 0" />
      <geometry>
        <mesh
          filename="package://srs-77dof/meshes/link-l2.STL" />
      </geometry>
      <material
        name="">
        <color
          rgba="0.890196078431372 0.890196078431372 0.913725490196078 1" />
      </material>
    </visual>
    <collision>
      <origin
        xyz="0 0 0"
        rpy="0 0 0" />
      <geometry>
        <mesh
          filename="package://srs-77dof/meshes/link-l2.STL" />
      </geometry>
    </collision>
  </link>
  <joint
    name="joint-l2"
    type="revolute">
    <origin
      xyz="0 0 0"
      rpy="-1.5708 -1.5708 0" />
    <parent
      link="link-l1" />
    <child
      link="link-l2" />
    <axis
      xyz="1 0 0" />
    <limit
      lower="-6.28"
      upper="6.28"
      effort="150"
      velocity="3.15" />
    <safety_controller
      k_velocity="0" />
  </joint>
  <link
    name="link-l3">
    <inertial>
      <origin
        xyz="0.259675633888232 -0.000106676988941984 0.00217885119538147"
        rpy="0 0 0" />
      <mass
        value="1.50985052864978" />
      <inertia
        ixx="0.00115086929397749"
        ixy="4.33533567138957E-06"
        ixz="-6.94920217562198E-05"
        iyy="0.00116566110978056"
        iyz="7.97846565209425E-07"
        izz="0.00168084898344929" />
    </inertial>
    <visual>
      <origin
        xyz="0 0 0"
        rpy="0 0 0" />
      <geometry>
        <mesh
          filename="package://srs-77dof/meshes/link-l3.STL" />
      </geometry>
      <material
        name="">
        <color
          rgba="0.501960784313725 1 0.501960784313725 1" />
      </material>
    </visual>
    <collision>
      <origin
        xyz="0 0 0"
        rpy="0 0 0" />
      <geometry>
        <mesh
          filename="package://srs-77dof/meshes/link-l3.STL" />
      </geometry>
    </collision>
  </link>
  <joint
    name="joint-l3"
    type="revolute">
    <origin
      xyz="0 0 0"
      rpy="-1.5708 -1.5708 0" />
    <parent
      link="link-l2" />
    <child
      link="link-l3" />
    <axis
      xyz="1 0 0" />
    <limit
      lower="-6.28"
      upper="6.28"
      effort="150"
      velocity="3.15" />
    <safety_controller
      k_velocity="0" />
  </joint>
  <link
    name="link-l4">
    <inertial>
      <origin
        xyz="8.95972747452234E-05 0.154540593767959 0.0186572319008282"
        rpy="0 0 0" />
      <mass
        value="2.0375685441998" />
      <inertia
        ixx="0.0035086949006757"
        ixy="-1.27726380733596E-07"
        ixz="4.91691735984302E-06"
        iyy="0.00209566567303361"
        iyz="0.000129132028633286"
        izz="0.00385581711303881" />
    </inertial>
    <visual>
      <origin
        xyz="0 0 0"
        rpy="0 0 0" />
      <geometry>
        <mesh
          filename="package://srs-77dof/meshes/link-l4.STL" />
      </geometry>
      <material
        name="">
        <color
          rgba="1 1 0 1" />
      </material>
    </visual>
    <collision>
      <origin
        xyz="0 0 0"
        rpy="0 0 0" />
      <geometry>
        <mesh
          filename="package://srs-77dof/meshes/link-l4.STL" />
      </geometry>
    </collision>
  </link>
  <joint
    name="joint-l4"
    type="revolute">
    <origin
      xyz="0.2651 -4E-05 0"
      rpy="0 0 0" />
    <parent
      link="link-l3" />
    <child
      link="link-l4" />
    <axis
      xyz="0 0 1" />
    <limit
      lower="-6.28"
      upper="6.28"
      effort="150"
      velocity="3.15" />
    <safety_controller
      k_velocity="0" />
  </joint>
  <link
    name="link-l5">
    <inertial>
      <origin
        xyz="6.66769830667824E-05 -0.00217885119119121 -0.00542436610779912"
        rpy="0 0 0" />
      <mass
        value="1.50985052900885" />
      <inertia
        ixx="0.00116566107703464"
        ixy="7.97721865939706E-07"
        ixz="-4.33544255100565E-06"
        iyy="0.00168084891490913"
        iyz="6.94920361841204E-05"
        izz="0.00115086918828793" />
    </inertial>
    <visual>
      <origin
        xyz="0 0 0"
        rpy="0 0 0" />
      <geometry>
        <mesh
          filename="package://srs-77dof/meshes/link-l5.STL" />
      </geometry>
      <material
        name="">
        <color
          rgba="0.501960784313725 1 0.501960784313725 1" />
      </material>
    </visual>
    <collision>
      <origin
        xyz="0 0 0"
        rpy="0 0 0" />
      <geometry>
        <mesh
          filename="package://srs-77dof/meshes/link-l5.STL" />
      </geometry>
    </collision>
  </link>
  <joint
    name="joint-l5"
    type="revolute">
    <origin
      xyz="0 0.2653 0.00015"
      rpy="-1.5708 0 0" />
    <parent
      link="link-l4" />
    <child
      link="link-l5" />
    <axis
      xyz="0 0 1" />
    <limit
      lower="-6.28"
      upper="6.28"
      effort="150"
      velocity="3.15" />
    <safety_controller
      k_velocity="0" />
  </joint>
  <link
    name="link-l6">
    <inertial>
      <origin
        xyz="-7.6501517041444E-05 0.102022290812947 0.0130540857764574"
        rpy="0 0 0" />
      <mass
        value="1.77721693197758" />
      <inertia
        ixx="0.00180718050523062"
        ixy="-1.26397649582924E-06"
        ixz="-4.38374372500402E-06"
        iyy="0.00186256025614885"
        iyz="-3.94961251824988E-05"
        izz="0.00195321821545571" />
    </inertial>
    <visual>
      <origin
        xyz="0 0 0"
        rpy="0 0 0" />
      <geometry>
        <mesh
          filename="package://srs-77dof/meshes/link-l6.STL" />
      </geometry>
      <material
        name="">
        <color
          rgba="1 1 0 1" />
      </material>
    </visual>
    <collision>
      <origin
        xyz="0 0 0"
        rpy="0 0 0" />
      <geometry>
        <mesh
          filename="package://srs-77dof/meshes/link-l6.STL" />
      </geometry>
    </collision>
  </link>
  <joint
    name="joint-l6"
    type="revolute">
    <origin
      xyz="0 0 0"
      rpy="1.5708 -1.5708 0" />
    <parent
      link="link-l5" />
    <child
      link="link-l6" />
    <axis
      xyz="0 0 1" />
    <limit
      lower="-6.28"
      upper="6.28"
      effort="150"
      velocity="3.15" />
    <safety_controller
      k_velocity="0" />
  </joint>
  <link
    name="link-l7">
    <inertial>
      <origin
        xyz="0.0853754957393848 -0.000179584046905934 -0.0214932787894448"
        rpy="0 0 0" />
      <mass
        value="0.30505900233751" />
      <inertia
        ixx="0.000275373809767483"
        ixy="-7.50029487418594E-07"
        ixz="-0.000160582257495832"
        iyy="0.00065924510271604"
        iyz="-2.48211323972738E-07"
        izz="0.000644204287144647" />
    </inertial>
    <visual>
      <origin
        xyz="0 0 0"
        rpy="0 0 0" />
      <geometry>
        <mesh
          filename="package://srs-77dof/meshes/link-l7.STL" />
      </geometry>
      <material
        name="">
        <color
          rgba="1 1 0 1" />
      </material>
    </visual>
    <collision>
      <origin
        xyz="0 0 0"
        rpy="0 0 0" />
      <geometry>
        <mesh
          filename="package://srs-77dof/meshes/link-l7.STL" />
      </geometry>
    </collision>
  </link>
  <joint
    name="joint-l7"
    type="revolute">
    <origin
      xyz="0 0 0"
      rpy="1.5708 0 0" />
    <parent
      link="link-l6" />
    <child
      link="link-l7" />
    <axis
      xyz="0 0 1" />
    <limit
      lower="-6.28"
      upper="6.28"
      effort="150"
      velocity="3.15" />
    <safety_controller
      k_velocity="0" />
  </joint>
  <link
    name="link-r1">
    <inertial>
      <origin
        xyz="-4.7875E-05 0.0023733 -0.0053507"
        rpy="0 0 0" />
      <mass
        value="2.8994" />
      <inertia
        ixx="0.0048887"
        ixy="-3.6961E-06"
        ixz="8.923E-06"
        iyy="0.0073417"
        iyz="0.00049999"
        izz="0.0050165" />
    </inertial>
    <visual>
      <origin
        xyz="0 0 0"
        rpy="0 0 0" />
      <geometry>
        <mesh
          filename="package://srs-77dof/meshes/link-r1.STL" />
      </geometry>
      <material
        name="">
        <color
          rgba="0 0.75294 0 1" />
      </material>
    </visual>
    <collision>
      <origin
        xyz="0 0 0"
        rpy="0 0 0" />
      <geometry>
        <mesh
          filename="package://srs-77dof/meshes/link-r1.STL" />
      </geometry>
    </collision>
  </link>
  <joint
    name="joint-r1"
    type="revolute">
    <origin
      xyz="0.3325 0 0.53254"
      rpy="3.14 -1.5708 0" />
    <parent
      link="base_link" />
    <child
      link="link-r1" />
    <axis
      xyz="0 0 -1" />
    <limit
      lower="-6.28"
      upper="6.28"
      effort="150"
      velocity="3.15" />
    <safety_controller
      k_velocity="0" />
  </joint>
  <link
    name="link-r2">
    <inertial>
      <origin
        xyz="7.4857E-07 -0.15091 -0.018075"
        rpy="0 0 0" />
      <mass
        value="4.4959" />
      <inertia
        ixx="0.0084063"
        ixy="-1.0925E-06"
        ixz="2.0948E-06"
        iyy="0.0060157"
        iyz="0.0009636"
        izz="0.0089821" />
    </inertial>
    <visual>
      <origin
        xyz="0 0 0"
        rpy="0 0 0" />
      <geometry>
        <mesh
          filename="package://srs-77dof/meshes/link-r2.STL" />
      </geometry>
      <material
        name="">
        <color
          rgba="0.8902 0.8902 0.91373 1" />
      </material>
    </visual>
    <collision>
      <origin
        xyz="0 0 0"
        rpy="0 0 0" />
      <geometry>
        <mesh
          filename="package://srs-77dof/meshes/link-r2.STL" />
      </geometry>
    </collision>
  </link>
  <joint
    name="joint-r2"
    type="revolute">
    <origin
      xyz="0 0 0"
      rpy="-1.5708 -1.5708 0" />
    <parent
      link="link-r1" />
    <child
      link="link-r2" />
    <axis
      xyz="0 0 1" />
    <limit
      lower="-6.28"
      upper="6.28"
      effort="150"
      velocity="3.15" />
    <safety_controller
      k_velocity="0" />
  </joint>
  <link
    name="link-r3">
    <inertial>
      <origin
        xyz="0.000108887236810712 0.00217841355489418 0.259675970068715"
        rpy="0 0 0" />
      <mass
        value="1.50987241060898" />
      <inertia
        ixx="0.0011656428813433"
        ixy="-7.92492089633067E-07"
        ixz="-4.28338820870899E-06"
        iyy="0.00168084394355416"
        iyz="-6.94864472539866E-05"
        izz="0.00115087964808608" />
    </inertial>
    <visual>
      <origin
        xyz="0 0 0"
        rpy="0 0 0" />
      <geometry>
        <mesh
          filename="package://srs-77dof/meshes/link-r3.STL" />
      </geometry>
      <material
        name="">
        <color
          rgba="0.501960784313725 1 0.501960784313725 1" />
      </material>
    </visual>
    <collision>
      <origin
        xyz="0 0 0"
        rpy="0 0 0" />
      <geometry>
        <mesh
          filename="package://srs-77dof/meshes/link-r3.STL" />
      </geometry>
    </collision>
  </link>
  <joint
    name="joint-r3"
    type="revolute">
    <origin
      xyz="0 0 0"
      rpy="1.5708 1.5708 0" />
    <parent
      link="link-r2" />
    <child
      link="link-r3" />
    <axis
      xyz="0 0 1" />
    <limit
      lower="-6.28"
      upper="6.28"
      effort="150"
      velocity="3.15" />
    <safety_controller
      k_velocity="0" />
  </joint>
  <link
    name="link-r4">
    <inertial>
      <origin
        xyz="-1.0925E-05 -0.15454 -0.018657"
        rpy="0 0 0" />
      <mass
        value="2.0376" />
      <inertia
        ixx="0.0035087"
        ixy="-1.4626E-06"
        ixz="3.7018E-06"
        iyy="0.0020957"
        iyz="0.00012913"
        izz="0.0038558" />
    </inertial>
    <visual>
      <origin
        xyz="0 0 0"
        rpy="0 0 0" />
      <geometry>
        <mesh
          filename="package://srs-77dof/meshes/link-r4.STL" />
      </geometry>
      <material
        name="">
        <color
          rgba="1 1 0 1" />
      </material>
    </visual>
    <collision>
      <origin
        xyz="0 0 0"
        rpy="0 0 0" />
      <geometry>
        <mesh
          filename="package://srs-77dof/meshes/link-r4.STL" />
      </geometry>
    </collision>
  </link>
  <joint
    name="joint-r4"
    type="revolute">
    <origin
      xyz="4E-05 0 0.2651"
      rpy="1.5708 1.5708 0" />
    <parent
      link="link-r3" />
    <child
      link="link-r4" />
    <axis
      xyz="0 0 -1" />
    <limit
      lower="-6.28"
      upper="6.28"
      effort="150"
      velocity="3.15" />
    <safety_controller
      k_velocity="0" />
  </joint>
  <link
    name="link-r5">
    <inertial>
      <origin
        xyz="-6.8887E-05 -0.0021784 -0.005424"
        rpy="0 0 0" />
      <mass
        value="1.5099" />
      <inertia
        ixx="0.0011656"
        ixy="-7.9249E-07"
        ixz="4.2834E-06"
        iyy="0.0016808"
        iyz="6.9486E-05"
        izz="0.0011509" />
    </inertial>
    <visual>
      <origin
        xyz="0 0 0"
        rpy="0 0 0" />
      <geometry>
        <mesh
          filename="package://srs-77dof/meshes/link-r5.STL" />
      </geometry>
      <material
        name="">
        <color
          rgba="0.50196 1 0.50196 1" />
      </material>
    </visual>
    <collision>
      <origin
        xyz="0 0 0"
        rpy="0 0 0" />
      <geometry>
        <mesh
          filename="package://srs-77dof/meshes/link-r5.STL" />
      </geometry>
    </collision>
  </link>
  <joint
    name="joint-r5"
    type="revolute">
    <origin
      xyz="0 -0.2653 -0.00015"
      rpy="1.5708 0 0" />
    <parent
      link="link-r4" />
    <child
      link="link-r5" />
    <axis
      xyz="0 0 1" />
    <limit
      lower="-6.28"
      upper="6.28"
      effort="150"
      velocity="3.15" />
    <safety_controller
      k_velocity="0" />
  </joint>
  <link
    name="link-r6">
    <inertial>
      <origin
        xyz="3.8669E-05 0.10202 0.013054"
        rpy="0 0 0" />
      <mass
        value="1.7772" />
      <inertia
        ixx="0.0018072"
        ixy="3.2661E-07"
        ixz="4.2347E-06"
        iyy="0.0018626"
        iyz="-3.9491E-05"
        izz="0.0019532" />
    </inertial>
    <visual>
      <origin
        xyz="0 0 0"
        rpy="0 0 0" />
      <geometry>
        <mesh
          filename="package://srs-77dof/meshes/link-r6.STL" />
      </geometry>
      <material
        name="">
        <color
          rgba="1 1 0 1" />
      </material>
    </visual>
    <collision>
      <origin
        xyz="0 0 0"
        rpy="0 0 0" />
      <geometry>
        <mesh
          filename="package://srs-77dof/meshes/link-r6.STL" />
      </geometry>
    </collision>
  </link>
  <joint
    name="joint-r6"
    type="revolute">
    <origin
      xyz="0 0 0"
      rpy="1.5708 1.5708 0" />
    <parent
      link="link-r5" />
    <child
      link="link-r6" />
    <axis
      xyz="0 0 1" />
    <limit
      lower="-6.28"
      upper="6.28"
      effort="150"
      velocity="3.15" />
    <safety_controller
      k_velocity="0" />
  </joint>
  <link
    name="link-r7">
    <inertial>
      <origin
        xyz="0.00012027 -0.085375 -0.021494"
        rpy="0 0 0" />
      <mass
        value="0.30506" />
      <inertia
        ixx="0.00065925"
        ixy="2.8632E-07"
        ixz="-1.6632E-07"
        iyy="0.00027538"
        iyz="0.00016058"
        izz="0.0006442" />
    </inertial>
    <visual>
      <origin
        xyz="0 0 0"
        rpy="0 0 0" />
      <geometry>
        <mesh
          filename="package://srs-77dof/meshes/link-r7.STL" />
      </geometry>
      <material
        name="">
        <color
          rgba="1 1 0 1" />
      </material>
    </visual>
    <collision>
      <origin
        xyz="0 0 0"
        rpy="0 0 0" />
      <geometry>
        <mesh
          filename="package://srs-77dof/meshes/link-r7.STL" />
      </geometry>
    </collision>
  </link>
  <joint
    name="joint-r7"
    type="revolute">
    <origin
      xyz="0 0 0"
      rpy="1.5708 1.5708 0" />
    <parent
      link="link-r6" />
    <child
      link="link-r7" />
    <axis
      xyz="0 0 1" />
    <limit
      lower="-6.28"
      upper="6.28"
      effort="150"
      velocity="3.15" />
    <safety_controller
      k_velocity="0" />
  </joint>
</robot>
